SLURM_NTASKS_PER_NODE=2
SLURM_NNODES=2
WORLD_SIZE=4
MASTER_ADDR=dcs172
MASTER_PORT=12975
NODE_RANK=0
[W socket.cpp:426] [c10d] The server socket has failed to listen on [::]:12975 (errno: 98 - Address already in use).
[W socket.cpp:426] [c10d] The server socket has failed to bind to 0.0.0.0:12975 (errno: 98 - Address already in use).
[E socket.cpp:462] [c10d] The server socket has failed to listen on any local network address.
Traceback (most recent call last):
  File "/gpfs/u/scratch/NLUG/shared/partial-asr/finetune_on_the_fly.py", line 24, in <module>
Traceback (most recent call last):
  File "/gpfs/u/scratch/NLUG/shared/partial-asr/finetune_on_the_fly.py", line 24, in <module>
Traceback (most recent call last):
Traceback (most recent call last):
  File "/gpfs/u/scratch/NLUG/shared/partial-asr/finetune_on_the_fly.py", line 24, in <module>
  File "/gpfs/u/scratch/NLUG/shared/partial-asr/finetune_on_the_fly.py", line 24, in <module>
Traceback (most recent call last):
Traceback (most recent call last):
  File "/gpfs/u/scratch/NLUG/shared/partial-asr/finetune_on_the_fly.py", line 24, in <module>
  File "/gpfs/u/scratch/NLUG/shared/partial-asr/finetune_on_the_fly.py", line 24, in <module>
    from peft import (
ModuleNotFoundError: No module named 'peft'
    from peft import (
    from peft import (
ModuleNotFoundError: No module named 'peft'
ModuleNotFoundError: No module named 'peft'
    from peft import (
ModuleNotFoundError: No module named 'peft'
Traceback (most recent call last):
Traceback (most recent call last):
  File "/gpfs/u/scratch/NLUG/shared/partial-asr/finetune_on_the_fly.py", line 24, in <module>
  File "/gpfs/u/scratch/NLUG/shared/partial-asr/finetune_on_the_fly.py", line 24, in <module>
    from peft import (
    ModuleNotFoundErrorfrom peft import (: 
No module named 'peft'
ModuleNotFoundError: No module named 'peft'
        from peft import (from peft import (

ModuleNotFoundErrorModuleNotFoundError: : No module named 'peft'No module named 'peft'

ERROR:torch.distributed.elastic.multiprocessing.api:failed (exitcode: 1) local_rank: 0 (pid: 1448145) of binary: /gpfs/u/home/NLUG/NLUGfbbr/scratch/miniconda3ppc/envs/venv_ppc/bin/python
ERROR:torch.distributed.elastic.multiprocessing.api:failed (exitcode: 1) local_rank: 0 (pid: 1448144) of binary: /gpfs/u/home/NLUG/NLUGfbbr/scratch/miniconda3ppc/envs/venv_ppc/bin/python
ERROR:torch.distributed.elastic.multiprocessing.api:failed (exitcode: 1) local_rank: 0 (pid: 1451453) of binary: /gpfs/u/home/NLUG/NLUGfbbr/scratch/miniconda3ppc/envs/venv_ppc/bin/python
ERROR:torch.distributed.elastic.multiprocessing.api:failed (exitcode: 1) local_rank: 0 (pid: 1451454) of binary: /gpfs/u/home/NLUG/NLUGfbbr/scratch/miniconda3ppc/envs/venv_ppc/bin/python
Traceback (most recent call last):
  File "/gpfs/u/home/NLUG/NLUGfbbr/scratch/miniconda3ppc/envs/venv_ppc/bin/torchrun", line 11, in <module>
    sys.exit(main())
  File "/gpfs/u/home/NLUG/NLUGfbbr/scratch/miniconda3ppc/envs/venv_ppc/lib/python3.10/site-packages/torch/distributed/elastic/multiprocessing/errors/__init__.py", line 346, in wrapper
    return f(*args, **kwargs)
  File "/gpfs/u/home/NLUG/NLUGfbbr/scratch/miniconda3ppc/envs/venv_ppc/lib/python3.10/site-packages/torch/distributed/run.py", line 762, in main
    run(args)
  File "/gpfs/u/home/NLUG/NLUGfbbr/scratch/miniconda3ppc/envs/venv_ppc/lib/python3.10/site-packages/torch/distributed/run.py", line 753, in run
    elastic_launch(
  File "/gpfs/u/home/NLUG/NLUGfbbr/scratch/miniconda3ppc/envs/venv_ppc/lib/python3.10/site-packages/torch/distributed/launcher/api.py", line 132, in __call__
    return launch_agent(self._config, self._entrypoint, list(args))
  File "/gpfs/u/home/NLUG/NLUGfbbr/scratch/miniconda3ppc/envs/venv_ppc/lib/python3.10/site-packages/torch/distributed/launcher/api.py", line 246, in launch_agent
    raise ChildFailedError(
torch.distributed.elastic.multiprocessing.errors.ChildFailedError: 
============================================================
finetune_on_the_fly.py FAILED
------------------------------------------------------------
Failures:
[1]:
  time      : 2024-09-28_14:34:23
  host      : dcs173.ccni.rpi.edu
  rank      : 7 (local_rank: 1)
  exitcode  : 1 (pid: 1451456)
  error_file: <N/A>
  traceback : To enable traceback see: https://pytorch.org/docs/stable/elastic/errors.html
------------------------------------------------------------
Root Cause (first observed failure):
[0]:
  time      : 2024-09-28_14:34:23
  host      : dcs173.ccni.rpi.edu
  rank      : 6 (local_rank: 0)
  exitcode  : 1 (pid: 1451454)
  error_file: <N/A>
  traceback : To enable traceback see: https://pytorch.org/docs/stable/elastic/errors.html
============================================================
Traceback (most recent call last):
  File "/gpfs/u/home/NLUG/NLUGfbbr/scratch/miniconda3ppc/envs/venv_ppc/bin/torchrun", line 11, in <module>
Traceback (most recent call last):
  File "/gpfs/u/home/NLUG/NLUGfbbr/scratch/miniconda3ppc/envs/venv_ppc/bin/torchrun", line 11, in <module>
    sys.exit(main())
  File "/gpfs/u/home/NLUG/NLUGfbbr/scratch/miniconda3ppc/envs/venv_ppc/lib/python3.10/site-packages/torch/distributed/elastic/multiprocessing/errors/__init__.py", line 346, in wrapper
    sys.exit(main())
  File "/gpfs/u/home/NLUG/NLUGfbbr/scratch/miniconda3ppc/envs/venv_ppc/lib/python3.10/site-packages/torch/distributed/elastic/multiprocessing/errors/__init__.py", line 346, in wrapper
Traceback (most recent call last):
  File "/gpfs/u/home/NLUG/NLUGfbbr/scratch/miniconda3ppc/envs/venv_ppc/bin/torchrun", line 11, in <module>
    return f(*args, **kwargs)
  File "/gpfs/u/home/NLUG/NLUGfbbr/scratch/miniconda3ppc/envs/venv_ppc/lib/python3.10/site-packages/torch/distributed/run.py", line 762, in main
    return f(*args, **kwargs)
  File "/gpfs/u/home/NLUG/NLUGfbbr/scratch/miniconda3ppc/envs/venv_ppc/lib/python3.10/site-packages/torch/distributed/run.py", line 762, in main
    run(args)
  File "/gpfs/u/home/NLUG/NLUGfbbr/scratch/miniconda3ppc/envs/venv_ppc/lib/python3.10/site-packages/torch/distributed/run.py", line 753, in run
    sys.exit(main())
  File "/gpfs/u/home/NLUG/NLUGfbbr/scratch/miniconda3ppc/envs/venv_ppc/lib/python3.10/site-packages/torch/distributed/elastic/multiprocessing/errors/__init__.py", line 346, in wrapper
    elastic_launch(
  File "/gpfs/u/home/NLUG/NLUGfbbr/scratch/miniconda3ppc/envs/venv_ppc/lib/python3.10/site-packages/torch/distributed/launcher/api.py", line 132, in __call__
    return f(*args, **kwargs)
  File "/gpfs/u/home/NLUG/NLUGfbbr/scratch/miniconda3ppc/envs/venv_ppc/lib/python3.10/site-packages/torch/distributed/run.py", line 762, in main
    return launch_agent(self._config, self._entrypoint, list(args))
  File "/gpfs/u/home/NLUG/NLUGfbbr/scratch/miniconda3ppc/envs/venv_ppc/lib/python3.10/site-packages/torch/distributed/launcher/api.py", line 246, in launch_agent
    run(args)
  File "/gpfs/u/home/NLUG/NLUGfbbr/scratch/miniconda3ppc/envs/venv_ppc/lib/python3.10/site-packages/torch/distributed/run.py", line 753, in run
    raise ChildFailedError(
torch.distributed.elastic.multiprocessing.errors.ChildFailedError: 
============================================================
finetune_on_the_fly.py FAILED
------------------------------------------------------------
Failures:
[1]:
  time      : 2024-09-28_14:34:23
  host      : dcs173.ccni.rpi.edu
  rank      : 5 (local_rank: 1)
  exitcode  : 1 (pid: 1451455)
  error_file: <N/A>
  traceback : To enable traceback see: https://pytorch.org/docs/stable/elastic/errors.html
------------------------------------------------------------
Root Cause (first observed failure):
[0]:
  time      : 2024-09-28_14:34:23
  host      : dcs173.ccni.rpi.edu
  rank      : 4 (local_rank: 0)
  exitcode  : 1 (pid: 1451453)
  error_file: <N/A>
  traceback : To enable traceback see: https://pytorch.org/docs/stable/elastic/errors.html
    run(args)
  File "/gpfs/u/home/NLUG/NLUGfbbr/scratch/miniconda3ppc/envs/venv_ppc/lib/python3.10/site-packages/torch/distributed/run.py", line 753, in run
============================================================
    elastic_launch(
  File "/gpfs/u/home/NLUG/NLUGfbbr/scratch/miniconda3ppc/envs/venv_ppc/lib/python3.10/site-packages/torch/distributed/launcher/api.py", line 132, in __call__
    return launch_agent(self._config, self._entrypoint, list(args))
  File "/gpfs/u/home/NLUG/NLUGfbbr/scratch/miniconda3ppc/envs/venv_ppc/lib/python3.10/site-packages/torch/distributed/launcher/api.py", line 246, in launch_agent
    raise ChildFailedError(
torch.distributed.elastic.multiprocessing.errors.ChildFailedError: 
============================================================
finetune_on_the_fly.py FAILED
------------------------------------------------------------
Failures:
[1]:
  time      : 2024-09-28_14:34:23
  host      : dcs172.ccni.rpi.edu
  rank      : 1 (local_rank: 1)
  exitcode  : 1 (pid: 1448146)
  error_file: <N/A>
  traceback : To enable traceback see: https://pytorch.org/docs/stable/elastic/errors.html
------------------------------------------------------------
Root Cause (first observed failure):
[0]:
  time      : 2024-09-28_14:34:23
  host      : dcs172.ccni.rpi.edu
  rank      : 0 (local_rank: 0)
  exitcode  : 1 (pid: 1448144)
  error_file: <N/A>
  traceback : To enable traceback see: https://pytorch.org/docs/stable/elastic/errors.html
============================================================
    elastic_launch(
  File "/gpfs/u/home/NLUG/NLUGfbbr/scratch/miniconda3ppc/envs/venv_ppc/lib/python3.10/site-packages/torch/distributed/launcher/api.py", line 132, in __call__
    return launch_agent(self._config, self._entrypoint, list(args))
  File "/gpfs/u/home/NLUG/NLUGfbbr/scratch/miniconda3ppc/envs/venv_ppc/lib/python3.10/site-packages/torch/distributed/launcher/api.py", line 246, in launch_agent
    raise ChildFailedError(
torch.distributed.elastic.multiprocessing.errors.ChildFailedError: 
============================================================
finetune_on_the_fly.py FAILED
------------------------------------------------------------
Failures:
[1]:
  time      : 2024-09-28_14:34:23
  host      : dcs172.ccni.rpi.edu
  rank      : 3 (local_rank: 1)
  exitcode  : 1 (pid: 1448147)
  error_file: <N/A>
  traceback : To enable traceback see: https://pytorch.org/docs/stable/elastic/errors.html
------------------------------------------------------------
Root Cause (first observed failure):
[0]:
  time      : 2024-09-28_14:34:23
  host      : dcs172.ccni.rpi.edu
  rank      : 2 (local_rank: 0)
  exitcode  : 1 (pid: 1448145)
  error_file: <N/A>
  traceback : To enable traceback see: https://pytorch.org/docs/stable/elastic/errors.html
============================================================
srun: error: dcs173: tasks 2-3: Exited with exit code 1
srun: error: dcs172: tasks 0-1: Exited with exit code 1
